{
 "cells": [
  {
   "cell_type": "code",
   "execution_count": 1,
   "metadata": {},
   "outputs": [],
   "source": [
    "import pandas as pd\n",
    "import numpy as np\n",
    "from delai.ml_logic.preprocessing import preprocess_X, preprocess_y\n",
    "from delai.data.local_disk import get_pandas_chunk"
   ]
  },
  {
   "cell_type": "code",
   "execution_count": 2,
   "metadata": {},
   "outputs": [
    {
     "name": "stdout",
     "output_type": "stream",
     "text": [
      "✅ preprocess_X() done\n",
      "✅ preprocess_y() done\n"
     ]
    }
   ],
   "source": [
    "df_X = pd.read_csv('../raw_data/initial_X_train.csv')\n",
    "df_y = pd.read_csv('../raw_data/initial_y_train.csv')\n",
    "\n",
    "X = preprocess_X(df_X)\n",
    "y = preprocess_y(df_y)"
   ]
  },
  {
   "cell_type": "code",
   "execution_count": 3,
   "metadata": {},
   "outputs": [],
   "source": [
    "from sklearn.model_selection import train_test_split\n",
    "X_train, X_test, y_train, y_test = train_test_split(X, y, test_size=0.3)"
   ]
  },
  {
   "cell_type": "code",
   "execution_count": 6,
   "metadata": {},
   "outputs": [
    {
     "ename": "ValueError",
     "evalue": "\nAll the 5 fits failed.\nIt is very likely that your model is misconfigured.\nYou can try to debug the error by setting error_score='raise'.\n\nBelow are more details about the failures:\n--------------------------------------------------------------------------------\n5 fits failed with the following error:\nTraceback (most recent call last):\n  File \"/Users/sameriliya/.pyenv/versions/3.8.12/envs/delai/lib/python3.8/site-packages/sklearn/model_selection/_validation.py\", line 686, in _fit_and_score\n    estimator.fit(X_train, y_train, **fit_params)\n  File \"/Users/sameriliya/.pyenv/versions/3.8.12/envs/delai/lib/python3.8/site-packages/sklearn/linear_model/_stochastic_gradient.py\", line 890, in fit\n    return self._fit(\n  File \"/Users/sameriliya/.pyenv/versions/3.8.12/envs/delai/lib/python3.8/site-packages/sklearn/linear_model/_stochastic_gradient.py\", line 677, in _fit\n    if self.average > 0:\nTypeError: '>' not supported between instances of 'str' and 'int'\n",
     "output_type": "error",
     "traceback": [
      "\u001b[0;31m---------------------------------------------------------------------------\u001b[0m",
      "\u001b[0;31mValueError\u001b[0m                                Traceback (most recent call last)",
      "Cell \u001b[0;32mIn [6], line 6\u001b[0m\n\u001b[1;32m      2\u001b[0m \u001b[39mfrom\u001b[39;00m \u001b[39msklearn\u001b[39;00m\u001b[39m.\u001b[39;00m\u001b[39mlinear_model\u001b[39;00m \u001b[39mimport\u001b[39;00m SGDClassifier\n\u001b[1;32m      4\u001b[0m sgd_model \u001b[39m=\u001b[39m SGDClassifier(loss\u001b[39m=\u001b[39m\u001b[39m'\u001b[39m\u001b[39mlog_loss\u001b[39m\u001b[39m'\u001b[39m, average\u001b[39m=\u001b[39m\u001b[39m'\u001b[39m\u001b[39mWeighted\u001b[39m\u001b[39m'\u001b[39m)\n\u001b[0;32m----> 6\u001b[0m cv_results \u001b[39m=\u001b[39m cross_validate(sgd_model, X, y, cv\u001b[39m=\u001b[39;49m\u001b[39m5\u001b[39;49m, scoring \u001b[39m=\u001b[39;49m \u001b[39m'\u001b[39;49m\u001b[39mrecall\u001b[39;49m\u001b[39m'\u001b[39;49m)\n\u001b[1;32m      7\u001b[0m cv_results\n",
      "File \u001b[0;32m~/.pyenv/versions/3.8.12/envs/delai/lib/python3.8/site-packages/sklearn/model_selection/_validation.py:285\u001b[0m, in \u001b[0;36mcross_validate\u001b[0;34m(estimator, X, y, groups, scoring, cv, n_jobs, verbose, fit_params, pre_dispatch, return_train_score, return_estimator, error_score)\u001b[0m\n\u001b[1;32m    265\u001b[0m parallel \u001b[39m=\u001b[39m Parallel(n_jobs\u001b[39m=\u001b[39mn_jobs, verbose\u001b[39m=\u001b[39mverbose, pre_dispatch\u001b[39m=\u001b[39mpre_dispatch)\n\u001b[1;32m    266\u001b[0m results \u001b[39m=\u001b[39m parallel(\n\u001b[1;32m    267\u001b[0m     delayed(_fit_and_score)(\n\u001b[1;32m    268\u001b[0m         clone(estimator),\n\u001b[0;32m   (...)\u001b[0m\n\u001b[1;32m    282\u001b[0m     \u001b[39mfor\u001b[39;00m train, test \u001b[39min\u001b[39;00m cv\u001b[39m.\u001b[39msplit(X, y, groups)\n\u001b[1;32m    283\u001b[0m )\n\u001b[0;32m--> 285\u001b[0m _warn_or_raise_about_fit_failures(results, error_score)\n\u001b[1;32m    287\u001b[0m \u001b[39m# For callabe scoring, the return type is only know after calling. If the\u001b[39;00m\n\u001b[1;32m    288\u001b[0m \u001b[39m# return type is a dictionary, the error scores can now be inserted with\u001b[39;00m\n\u001b[1;32m    289\u001b[0m \u001b[39m# the correct key.\u001b[39;00m\n\u001b[1;32m    290\u001b[0m \u001b[39mif\u001b[39;00m callable(scoring):\n",
      "File \u001b[0;32m~/.pyenv/versions/3.8.12/envs/delai/lib/python3.8/site-packages/sklearn/model_selection/_validation.py:367\u001b[0m, in \u001b[0;36m_warn_or_raise_about_fit_failures\u001b[0;34m(results, error_score)\u001b[0m\n\u001b[1;32m    360\u001b[0m \u001b[39mif\u001b[39;00m num_failed_fits \u001b[39m==\u001b[39m num_fits:\n\u001b[1;32m    361\u001b[0m     all_fits_failed_message \u001b[39m=\u001b[39m (\n\u001b[1;32m    362\u001b[0m         \u001b[39mf\u001b[39m\u001b[39m\"\u001b[39m\u001b[39m\\n\u001b[39;00m\u001b[39mAll the \u001b[39m\u001b[39m{\u001b[39;00mnum_fits\u001b[39m}\u001b[39;00m\u001b[39m fits failed.\u001b[39m\u001b[39m\\n\u001b[39;00m\u001b[39m\"\u001b[39m\n\u001b[1;32m    363\u001b[0m         \u001b[39m\"\u001b[39m\u001b[39mIt is very likely that your model is misconfigured.\u001b[39m\u001b[39m\\n\u001b[39;00m\u001b[39m\"\u001b[39m\n\u001b[1;32m    364\u001b[0m         \u001b[39m\"\u001b[39m\u001b[39mYou can try to debug the error by setting error_score=\u001b[39m\u001b[39m'\u001b[39m\u001b[39mraise\u001b[39m\u001b[39m'\u001b[39m\u001b[39m.\u001b[39m\u001b[39m\\n\u001b[39;00m\u001b[39m\\n\u001b[39;00m\u001b[39m\"\u001b[39m\n\u001b[1;32m    365\u001b[0m         \u001b[39mf\u001b[39m\u001b[39m\"\u001b[39m\u001b[39mBelow are more details about the failures:\u001b[39m\u001b[39m\\n\u001b[39;00m\u001b[39m{\u001b[39;00mfit_errors_summary\u001b[39m}\u001b[39;00m\u001b[39m\"\u001b[39m\n\u001b[1;32m    366\u001b[0m     )\n\u001b[0;32m--> 367\u001b[0m     \u001b[39mraise\u001b[39;00m \u001b[39mValueError\u001b[39;00m(all_fits_failed_message)\n\u001b[1;32m    369\u001b[0m \u001b[39melse\u001b[39;00m:\n\u001b[1;32m    370\u001b[0m     some_fits_failed_message \u001b[39m=\u001b[39m (\n\u001b[1;32m    371\u001b[0m         \u001b[39mf\u001b[39m\u001b[39m\"\u001b[39m\u001b[39m\\n\u001b[39;00m\u001b[39m{\u001b[39;00mnum_failed_fits\u001b[39m}\u001b[39;00m\u001b[39m fits failed out of a total of \u001b[39m\u001b[39m{\u001b[39;00mnum_fits\u001b[39m}\u001b[39;00m\u001b[39m.\u001b[39m\u001b[39m\\n\u001b[39;00m\u001b[39m\"\u001b[39m\n\u001b[1;32m    372\u001b[0m         \u001b[39m\"\u001b[39m\u001b[39mThe score on these train-test partitions for these parameters\u001b[39m\u001b[39m\"\u001b[39m\n\u001b[0;32m   (...)\u001b[0m\n\u001b[1;32m    376\u001b[0m         \u001b[39mf\u001b[39m\u001b[39m\"\u001b[39m\u001b[39mBelow are more details about the failures:\u001b[39m\u001b[39m\\n\u001b[39;00m\u001b[39m{\u001b[39;00mfit_errors_summary\u001b[39m}\u001b[39;00m\u001b[39m\"\u001b[39m\n\u001b[1;32m    377\u001b[0m     )\n",
      "\u001b[0;31mValueError\u001b[0m: \nAll the 5 fits failed.\nIt is very likely that your model is misconfigured.\nYou can try to debug the error by setting error_score='raise'.\n\nBelow are more details about the failures:\n--------------------------------------------------------------------------------\n5 fits failed with the following error:\nTraceback (most recent call last):\n  File \"/Users/sameriliya/.pyenv/versions/3.8.12/envs/delai/lib/python3.8/site-packages/sklearn/model_selection/_validation.py\", line 686, in _fit_and_score\n    estimator.fit(X_train, y_train, **fit_params)\n  File \"/Users/sameriliya/.pyenv/versions/3.8.12/envs/delai/lib/python3.8/site-packages/sklearn/linear_model/_stochastic_gradient.py\", line 890, in fit\n    return self._fit(\n  File \"/Users/sameriliya/.pyenv/versions/3.8.12/envs/delai/lib/python3.8/site-packages/sklearn/linear_model/_stochastic_gradient.py\", line 677, in _fit\n    if self.average > 0:\nTypeError: '>' not supported between instances of 'str' and 'int'\n"
     ]
    }
   ],
   "source": [
    "from sklearn.model_selection import cross_validate\n",
    "from sklearn.linear_model import SGDClassifier\n",
    "\n",
    "sgd_model = SGDClassifier(loss='log_loss', average=None)\n",
    "\n",
    "cv_results = cross_validate(sgd_model, X, y, cv=5, scoring = 'recall')\n",
    "cv_results\n"
   ]
  },
  {
   "cell_type": "code",
   "execution_count": null,
   "metadata": {},
   "outputs": [],
   "source": []
  }
 ],
 "metadata": {
  "kernelspec": {
   "display_name": "Python 3.8.12 64-bit ('delai')",
   "language": "python",
   "name": "python3"
  },
  "language_info": {
   "codemirror_mode": {
    "name": "ipython",
    "version": 3
   },
   "file_extension": ".py",
   "mimetype": "text/x-python",
   "name": "python",
   "nbconvert_exporter": "python",
   "pygments_lexer": "ipython3",
   "version": "3.8.12"
  },
  "orig_nbformat": 4,
  "vscode": {
   "interpreter": {
    "hash": "0875b2852ba53d04eef81221e37e4b35e2d8d6d991ba847490f1cdc34d293f04"
   }
  }
 },
 "nbformat": 4,
 "nbformat_minor": 2
}
